<?xml version="1.0" encoding="UTF-8"?>

<robot xmlns:xacro="http//www.ros.org/wiki/xacro" name="TwoLink_robot">

    <!--Define properties -->	
    <xacro:property name="Pi" value="3.14"/>
    
    <!-- Define materils -->
    <material name="blue">
        <color  rgba="0 0 1 1"/>
    </material>
    
    <material name="pink">
        <color rgba="0.49 0.31 0.47 1"/>
    </material>
    
    <material name="black">
        <color  rgba="0 0 0 1"/>
    </material>
    
    <!--Define links-->
    <link name="base_link">
        <visual>
            <geometry>
                <box size="0.2 0.2 0.03"/>
            </geometry>
            <origin xyz="0 0 0" rpy="0 0 0"/>
        </visual>
    </link> 

    <link name="arm1_link">
        <visual>
            <geometry>
                <cylinder radius="0.02" length="0.3"/>
            </geometry>
	    <material name="blue"/>
            <origin xyz="0 0 0.15" rpy="0 0 0"/>
        </visual>
    </link>
    
    <link name="arm2_link">
    	<visual>
    	    <geometry>
    	        <cylinder radius="0.02" length="0.4"/>
    	    </geometry>
    	    <origin xyz="0 0 0.2" rpy="0 0 0"/>
    	    <material name="pink"/>
    	</visual>
    </link>
    
    <link name="claw_support">
       <visual>
          <geometry>
             <box size="0.01 0.1 0.01"/>
          </geometry>
          <origin xyz="0 0 0.005" rpy="0 0 0"/>
          <material name="black"/>
       </visual>
    </link>
    
        <link name="left_gripper">
       <visual>
          <geometry>
             <box size="0.01 0.01 0.1"/>
          </geometry>
          <origin xyz="0 -0.005 0.05" rpy="0 0 0"/>
          <material name="black"/>
       </visual>
    </link>
    
   <link name="right_gripper">
       <visual>
          <geometry>
             <box size="0.01 0.01 0.1"/>
          </geometry>
          <origin xyz="0 0.005 0.05" rpy="0 0 0"/>
          <material name="black"/>
       </visual>
    </link>
    
    <!-- Define joints-->
    <joint name="base_arm1_joint" type="continuous">
    	<parent link="base_link"/>
    	<child  link="arm1_link"/>
    	<origin xyz="0 0 0" rpy="0 0 0"/>
    	<axis   xyz="0 0 1"/>
    </joint>
    
    <joint name="arm1_arm2_joint" type="revolute">
    	<parent link="arm1_link"/>
    	<child  link="arm2_link"/>
	<origin xyz="0 0 0.3" rpy="0 0 0"/>
	<axis   xyz="0 1 0"/>
	<limit lower="0" upper="${Pi}" effort="100" velocity="100"/>
   </joint>
   
   <joint name="arm2_claw_suppoer_joint" type="fixed">
       <parent link="arm2_link"/>
       <child  link="claw_support"/>
       <origin xyz="0 0 0.4" rpy="0 0 0"/>
   </joint>
   
   <joint name="claw_support_left_gripper_joint" type="revolute">
       <parent link="claw_support"/>
       <child  link="left_gripper"/>
       <origin xyz="0 -0.05 0" rpy="0 0 0"/>
       <axis   xyz="-1 0 0"/>
       <limit lower="0" upper="0.52" effort="100" velocity="100"/>
   </joint>
   
   <joint name="claw_support_right_gripper_joint" type="revolute">
       <parent link="claw_support"/>
       <child  link="right_gripper"/>
       <origin xyz="0 0.05 0" rpy="0 0 0"/>
       <axis   xyz="1 0 0"/>
       <limit lower="0" upper="0.52" effort="100" velocity="100"/>
       <mimic joint="claw_support_left_gripper_joint" multiplier="1"/>
   </joint>
      
</robot>
